<?xml version="1.0" encoding="utf-8" ?>
<!-- =================================================================================== -->
<!-- |    This document was autogenerated by xacro from /home/ws/ws_rmrobot/src/rm_robot/rm_65_description/urdf/rm_65.urdf.xacro | -->
<!-- |    EDITING THIS FILE BY HAND IS NOT RECOMMENDED                                 | -->
<!-- =================================================================================== -->
<robot name="rm_65">
    <link name="dummy" />
    <!--######################################################################-->
    <link name="base_link">
        
<inertial>
            <origin rpy="0 0 0" xyz="-0.000433277303987328 -3.54664423471128E-05 0.0599427668933796" />
            <mass value="14" />
            <inertia ixx="0.0017261110801622" ixy="2.52746264980217E-06" ixz="-3.67690303614961E-05" iyy="0.00170987405835604" iyz="1.67996364994424E-06" izz="0.000904023422915791" />
        </inertial>

        <visual>
            <origin rpy="0 0 0" xyz="0 0 0" />
            <geometry>
                <mesh filename="package://rm_65_description/meshes/base_link.STL" />
            </geometry>
            <material name="">
                <color rgba="1 1 1 1" />
            </material>
        </visual>
        <collision>
            <origin rpy="0 0 0" xyz="0 0 0" />
            <geometry>
                <mesh filename="package://rm_65_description/meshes/base_link.STL" />
            </geometry>
        </collision>
    </link>
    <gazebo reference="base_link">
        <mu1 value="200000.0" />
        <mu2 value="200000.0" />
        <kp value="100000000.0" />
        <kd value="1.0" />
    </gazebo>
    <joint name="dummy_joint" type="fixed">
        <parent link="dummy" />
        <child link="base_link" />
    </joint>
    <!--######################################################################-->
    <link name="Link1">
        
<inertial>
            <origin rpy="0 0 0" xyz="1.2226305431569E-08 0.0211079974844683 -0.0251854220842269" />
            <mass value="0.593563443690403" />
            <inertia ixx="0.00126614120341847" ixy="-1.294980943835E-08" ixz="-9.80120923066996E-09" iyy="0.00118168178300364" iyz="-0.00021121727444415" izz="0.00056135241627747" />
        </inertial>

        <visual>
            <origin rpy="0 0 0" xyz="0 0 0" />
            <geometry>
                <mesh filename="package://rm_65_description/meshes/link1.STL" />
            </geometry>
            <material name="">
                <color rgba="1 1 1 1" />
            </material>
        </visual>
        <collision>
            <origin rpy="0 0 0" xyz="0 0 0" />
            <geometry>
                <mesh filename="package://rm_65_description/meshes/link1.STL" />
            </geometry>
        </collision>
    </link>
    <joint name="joint1" type="revolute">
        <origin rpy="0 0 0" xyz="0 0 0.2405" />
        <parent link="base_link" />
        <child link="Link1" />
        <axis xyz="0 0 1" />
        <limit effort="60" lower="-3.14" upper="3.14" velocity="3.14" />
        <dynamics damping="50" friction="1" />
    </joint>
    <!--######################################################################-->
    <link name="Link2">
        
<inertial>
            <origin rpy="0 0 0" xyz="0.152256463426163 4.75383656106654E-07 -0.00620260383607792" />
            <mass value="0.864175046869043" />
            <inertia ixx="0.00089150298478414" ixy="-2.23268489334765E-08" ixz="0.00156246461035015" iyy="0.00733754343083901" iyz="6.28110889329165E-09" izz="0.00697869103915473" />
        </inertial>

        <visual>
            <origin rpy="0 0 0" xyz="0 0 0" />
            <geometry>
                <mesh filename="package://rm_65_description/meshes/link2.STL" />
            </geometry>
            <material name="">
                <color rgba="1 1 1 1" />
            </material>
        </visual>
        <collision>
            <origin rpy="0 0 0" xyz="0 0 0" />
            <geometry>
                <mesh filename="package://rm_65_description/meshes/link2.STL" />
            </geometry>
        </collision>
    </link>
    <joint name="joint2" type="revolute">
        <origin rpy="1.5708 -1.5708 0" xyz="0 0 0" />
        <parent link="Link1" />
        <child link="Link2" />
        <axis xyz="0 0 1" />
        <limit effort="60" lower="-2.268" upper="2.268" velocity="3.14" />
        <dynamics damping="50" friction="1" />
    </joint>
    <!--######################################################################-->
    <link name="Link3">
        
<inertial>
            <origin rpy="0 0 0" xyz="5.05312670989961E-06 -0.0595925663694732 0.010569069212336" />
            <mass value="0.289633681624654" />
            <inertia ixx="0.00063737100450158" ixy="-7.05261293649751E-08" ixz="-3.86643272239426E-08" iyy="0.00015648388095025" iyz="-0.00014461035994916" izz="0.000614178164773085" />
        </inertial>

        <visual>
            <origin rpy="0 0 0" xyz="0 0 0" />
            <geometry>
                <mesh filename="package://rm_65_description/meshes/link3.STL" />
            </geometry>
            <material name="">
                <color rgba="1 1 1 1" />
            </material>
        </visual>
        <collision>
            <origin rpy="0 0 0" xyz="0 0 0" />
            <geometry>
                <mesh filename="package://rm_65_description/meshes/link3.STL" />
            </geometry>
        </collision>
    </link>
    <joint name="joint3" type="revolute">
        <origin rpy="0 0 1.5708" xyz="0.256 0 0" />
        <parent link="Link2" />
        <child link="Link3" />
        <axis xyz="0 0 1" />
        <limit effort="30" lower="-2.355" upper="2.355" velocity="3.92" />
        <dynamics damping="50" friction="1" />
    </joint>
    <!--######################################################################-->
    <link name="Link4">
        
<inertial>
            <origin rpy="0 0 0" xyz="1.15516617405898E-06 -0.0180424468598241 -0.0215394748352687" />
            <mass value="0.239419768320061" />
            <inertia ixx="0.000285938919722783" ixy="3.07101359163101E-09" ixz="-2.21994118981953E-09" iyy="0.000262727540304212" iyz="4.4236583260078E-05" izz="0.000119888082791859" />
        </inertial>

        <visual>
            <origin rpy="0 0 0" xyz="0 0 0" />
            <geometry>
                <mesh filename="package://rm_65_description/meshes/link4.STL" />
            </geometry>
            <material name="">
                <color rgba="1 1 1 1" />
            </material>
        </visual>
        <collision>
            <origin rpy="0 0 0" xyz="0 0 0" />
            <geometry>
                <mesh filename="package://rm_65_description/meshes/link4.STL" />
            </geometry>
        </collision>
    </link>
    <joint name="joint4" type="revolute">
        <origin rpy="1.5708 0 0" xyz="0 -0.21 0" />
        <parent link="Link3" />
        <child link="Link4" />
        <axis xyz="0 0 1" />
        <limit effort="10" lower="-3.14" upper="3.14" velocity="3.92" />
        <dynamics damping="50" friction="1" />
    </joint>
    <!--######################################################################-->
    <link name="Link5">
        
<inertial>
            <origin rpy="0 0 0" xyz="3.19794786262152E-06 -0.0593808368101458 0.00736804250989326" />
            <mass value="0.218799761431678" />
            <inertia ixx="0.000350540363914072" ixy="-3.41781619975602E-08" ixz="-1.77056457224373E-08" iyy="0.000104927867487581" iyz="-7.82431228461971E-05" izz="0.000334482418423629" />
        </inertial>

        <visual>
            <origin rpy="0 0 0" xyz="0 0 0" />
            <geometry>
                <mesh filename="package://rm_65_description/meshes/link5.STL" />
            </geometry>
            <material name="">
                <color rgba="1 1 1 1" />
            </material>
        </visual>
        <collision>
            <origin rpy="0 0 0" xyz="0 0 0" />
            <geometry>
                <mesh filename="package://rm_65_description/meshes/link5.STL" />
            </geometry>
        </collision>
    </link>
    <joint name="joint5" type="revolute">
        <origin rpy="-1.5708 0 0" xyz="0 0 0" />
        <parent link="Link4" />
        <child link="Link5" />
        <axis xyz="0 0 1" />
        <limit effort="10" lower="-2.233" upper="2.233" velocity="3.92" />
        <dynamics damping="50" friction="1" />
    </joint>
    <!--######################################################################-->
    <link name="Link6">
        
<inertial>
            <origin rpy="0 0 0" xyz="0.000714234511756999 -0.000396718732824521 -0.0126723660946126" />
            <mass value="0.0649018034311231" />
            <inertia ixx="2.02766547502765E-05" ixy="-1.32505200276849E-06" ixz="-2.5845091522508E-08" iyy="1.87986725225022E-05" iyz="3.39471452125439E-09" izz="3.17885459163081E-05" />
        </inertial>

        <visual>
            <origin rpy="0 0 0" xyz="0 0 0" />
            <geometry>
                <mesh filename="package://rm_65_description/meshes/link6.STL" />
            </geometry>
            <material name="">
                <color rgba="1 1 1 1" />
            </material>
        </visual>
        <collision>
            <origin rpy="0 0 0" xyz="0 0 0" />
            <geometry>
                <mesh filename="package://rm_65_description/meshes/link6.STL" />
            </geometry>
        </collision>
    </link>
    <joint name="joint6" type="continuous">
        <origin rpy="1.5708 0 0" xyz="0 -0.144 0" />
        <parent link="Link5" />
        <child link="Link6" />
        <axis xyz="0 0 1" />
        <limit effort="10" lower="-6.28" upper="6.28" velocity="3.92" />
        <dynamics damping="50" friction="1" />
    </joint>
    <!--######################################################################-->
    <!-- This URDF was automatically created by SolidWorks to URDF Exporter! Originally created by Stephen Brawner (brawner@gmail.com) 
     Commit Version: 1.5.1-0-g916b5db  Build Version: 1.5.7152.31018
     For more information, please see http://wiki.ros.org/sw_urdf_exporter -->
    <!-- plate -->
    <link name="plate">
        
<inertial>
            <origin rpy="0 0 0" xyz="0.04582 -2.25539999752262E-10 0.004046" />
            <mass value="0.051308" />
            <inertia ixx="1.5915E-05" ixy="2.51849999912398E-14" ixz="1.4307E-07" iyy="8.6534E-05" iyz="4.91220000094025E-12" izz="0.00010189" />
        </inertial>

        <visual>
            <origin rpy="1.5707963267949 0 0" xyz="0 0 0" />
            <geometry>
                <mesh filename="package://rm_65_description/meshes/plate.STL" />
            </geometry>
            <material name="">
                <color rgba="1 1 1 1" />
            </material>
        </visual>
        <collision>
            <origin rpy="1.5707963267949 0 0" xyz="0 0 0" />
            <geometry>
                <mesh filename="package://rm_65_description/meshes/plate.STL" />
            </geometry>
        </collision>
    </link>
    <joint name="joint7" type="fixed">
        <origin rpy="0 0 3.1416" xyz="0 0 0" />
        <parent link="Link6" />
        <child link="plate" />
        <dynamics damping="50" friction="1" />
    </joint>
    <!-- INTEL REALSENSE D435 -->
    <!-- INTEL REALSENSE R200 -->
    <!-- camera body, with origin at bottom screw mount -->
    <joint name="d435_joint" type="fixed">
        <origin rpy="0 -1.5708 3.1416" xyz="0.08 0 0.0185" />
        <parent link="plate" />
        <child link="d435_bottom_screw_frame" />
    </joint>
    <link name="d435_bottom_screw_frame" />
    <joint name="d435_link_joint" type="fixed">
        <origin rpy="0 0 0" xyz="0 0.0175 0.0125" />
        <parent link="d435_bottom_screw_frame" />
        <child link="d435_link" />
    </joint>
    <link name="d435_link">
        <visual>
            <origin rpy="1.57079632679 0 1.57079632679" xyz="0.0149 -0.0175 0" />
            <geometry>
                <mesh filename="package://realsense_ros_gazebo/meshes/realsense_d435.stl" />
            </geometry>
        </visual>
        <collision>
            <origin rpy="0 0 0" xyz="0 -0.0175 0" />
            <geometry>
                <box size="0.02505 0.09 0.025" />
            </geometry>
        </collision>
        
<inertial>
            <mass value="0.564" />
            <origin rpy="0 0 0" xyz="0 -0.0175 0" />
            <inertia ixx="0.000410075" ixy="0" ixz="0" iyy="5.88676175e-05" iyz="0" izz="5.88676175e-05" />
        </inertial>

    </link>
    <!-- camera depth joints and links -->
    <joint name="d435_depth_joint" type="fixed">
        <origin rpy="0 0 0" xyz="0 0 0" />
        <parent link="d435_link" />
        <child link="d435_depth_frame" />
    </joint>
    <link name="d435_depth_frame" />
    <joint name="d435_depth_optical_joint" type="fixed">
        <origin rpy="-1.57079632679 0 -1.57079632679" xyz="0 0 0" />
        <parent link="d435_depth_frame" />
        <child link="d435_depth_optical_frame" />
    </joint>
    <link name="d435_depth_optical_frame" />
    <!-- camera left IR joints and links -->
    <joint name="d435_left_ir_joint" type="fixed">
        <origin rpy="0 0 0" xyz="0 0.0 0" />
        <parent link="d435_depth_frame" />
        <child link="d435_left_ir_frame" />
    </joint>
    <link name="d435_left_ir_frame" />
    <joint name="d435_left_ir_optical_joint" type="fixed">
        <origin rpy="-1.57079632679 0 -1.57079632679" xyz="0 0 0" />
        <parent link="d435_left_ir_frame" />
        <child link="d435_left_ir_optical_frame" />
    </joint>
    <link name="d435_left_ir_optical_frame" />
    <!-- camera right IR joints and links -->
    <joint name="d435_right_ir_joint" type="fixed">
        <origin rpy="0 0 0" xyz="0 -0.05 0" />
        <parent link="d435_depth_frame" />
        <child link="d435_right_ir_frame" />
    </joint>
    <link name="d435_right_ir_frame" />
    <joint name="d435_right_ir_optical_joint" type="fixed">
        <origin rpy="-1.57079632679 0 -1.57079632679" xyz="0 0 0" />
        <parent link="d435_right_ir_frame" />
        <child link="d435_right_ir_optical_frame" />
    </joint>
    <link name="d435_right_ir_optical_frame" />
    <!-- camera color joints and links -->
    <joint name="d435_color_joint" type="fixed">
        <origin rpy="0 0 0" xyz="0 0.015 0" />
        <parent link="d435_depth_frame" />
        <child link="d435_color_frame" />
    </joint>
    <link name="d435_color_frame" />
    <joint name="d435_color_optical_joint" type="fixed">
        <origin rpy="-1.57079632679 0 -1.57079632679" xyz="0 0 0" />
        <parent link="d435_color_frame" />
        <child link="d435_color_optical_frame" />
    </joint>
    <link name="d435_color_optical_frame" />
    <!-- gazebo plugin -->
    <gazebo reference="d435_link">
        <self_collide>0</self_collide>
        <enable_wind>0</enable_wind>
        <kinematic>0</kinematic>
        <gravity>1</gravity>
        <mu2>1</mu2>
        <fdir1>0 0 0</fdir1>
        <kp>1e+13</kp>
        <kd>1</kd>
        <sensor name="d435_color" type="camera">
            <camera name="d435">
                <horizontal_fov>1.21125850088</horizontal_fov>
                <image>
                    <width>640</width>
                    <height>480</height>
                    <format>RGB_INT8</format>
                </image>
                <clip>
                    <near>0.1</near>
                    <far>100</far>
                </clip>
                <noise>
                    <type>gaussian</type>
                    <mean>0.0</mean>
                    <stddev>0.007</stddev>
                </noise>
            </camera>
            <always_on>1</always_on>
            <update_rate>30</update_rate>
            <visualize>1</visualize>
        </sensor>
        <sensor name="d435_ired1" type="camera">
            <camera name="d435">
                <horizontal_fov>1.4870205227</horizontal_fov>
                <image>
                    <width>1280</width>
                    <height>720</height>
                    <format>L_INT8</format>
                </image>
                <clip>
                    <near>0.1</near>
                    <far>100</far>
                </clip>
                <noise>
                    <type>gaussian</type>
                    <mean>0.0</mean>
                    <stddev>0.05</stddev>
                </noise>
            </camera>
            <always_on>1</always_on>
            <update_rate>90</update_rate>
            <visualize>0</visualize>
        </sensor>
        <sensor name="d435_ired2" type="camera">
            <camera name="d435">
                <horizontal_fov>1.4870205227</horizontal_fov>
                <image>
                    <width>1280</width>
                    <height>720</height>
                    <format>L_INT8</format>
                </image>
                <clip>
                    <near>0.1</near>
                    <far>100</far>
                </clip>
                <noise>
                    <type>gaussian</type>
                    <mean>0.0</mean>
                    <stddev>0.05</stddev>
                </noise>
            </camera>
            <always_on>1</always_on>
            <update_rate>90</update_rate>
            <visualize>0</visualize>
        </sensor>
        <sensor name="d435_depth" type="depth">
            <camera name="d435">
                <horizontal_fov>1.4870205227</horizontal_fov>
                <image>
                    <width>1280</width>
                    <height>720</height>
                </image>
                <clip>
                    <near>0.1</near>
                    <far>100</far>
                </clip>
                <noise>
                    <type>gaussian</type>
                    <mean>0.0</mean>
                    <stddev>0.100</stddev>
                </noise>
            </camera>
            <always_on>1</always_on>
            <update_rate>90</update_rate>
            <visualize>0</visualize>
        </sensor>
    </gazebo>
    <gazebo>
        <plugin filename="librealsense_gazebo_plugin.so" name="d435">
            <prefix>d435_</prefix>
            <depthUpdateRate>10</depthUpdateRate>
            <colorUpdateRate>10</colorUpdateRate>
            <infraredUpdateRate>10</infraredUpdateRate>
            <depthTopicName>depth/image_raw</depthTopicName>
            <depthCameraInfoTopicName>depth/camera_info</depthCameraInfoTopicName>
            <colorTopicName>color/image_raw</colorTopicName>
            <colorCameraInfoTopicName>color/camera_info</colorCameraInfoTopicName>
            <infrared1TopicName>infra1/image_raw</infrared1TopicName>
            <infrared1CameraInfoTopicName>infra1/camera_info</infrared1CameraInfoTopicName>
            <infrared2TopicName>infra2/image_raw</infrared2TopicName>
            <infrared2CameraInfoTopicName>infra2/camera_info</infrared2CameraInfoTopicName>
            <colorOpticalframeName>d435_color_optical_frame</colorOpticalframeName>
            <depthOpticalframeName>d435_depth_optical_frame</depthOpticalframeName>
            <infrared1OpticalframeName>d435_infrared1_optical_frame</infrared1OpticalframeName>
            <infrared2OpticalframeName>d435_infrared2_optical_frame</infrared2OpticalframeName>
            <rangeMinDepth>0.2</rangeMinDepth>
            <rangeMaxDepth>10.0</rangeMaxDepth>
            <pointCloud>false</pointCloud>
            <pointCloudTopicName>depth/color/points</pointCloudTopicName>
            <pointCloudCutoff>0.25</pointCloudCutoff>
            <pointCloudCutoffMax>9.0</pointCloudCutoffMax>
        </plugin>
    </gazebo>
    <!--
  <xacro:arg name="use_nominal_extrinsics" default="false"/>
  <xacro:arg name="add_plug" default="false" />
  <xacro:arg name="use_mesh" default="true" />
  <xacro:include filename="$(find realsense2_description)/urdf/_d435.urdf.xacro" />

  <xacro:sensor_d435 parent="plate" use_nominal_extrinsics="$(arg use_nominal_extrinsics)" add_plug="$(arg add_plug)" use_mesh="$(arg use_mesh)">
    <origin xyz="0.08 0 0.0185" rpy="0 -1.5708 3.1416"/>
    <origin xyz="0.0925 0 0.008" rpy="0 -1.5708 0"/>
  </xacro:sensor_d435>
  -->
    <link name="gripper_base_link">
        
<inertial>
            <origin rpy="0 0 0" xyz="0.00339303654278191 -2.1205433560656E-05 -0.0099185365078758" />
            <mass value="0.105853592307918" />
            <inertia ixx="3.93795927851199E-05" ixy="-8.7395226509728E-08" ixz="5.91928672040786E-07" iyy="0.000106376720416166" iyz="-1.82858764303774E-10" izz="0.000125852616063213" />
        </inertial>

        <visual>
            <origin rpy="0 0 0" xyz="0 0 0" />
            <geometry>
                <mesh filename="package://rm_65_description/meshes/gripper_meshes/gripper_base_link.STL" />
            </geometry>
            <material name="">
                <color rgba="0.894117647058823 0.913725490196078 0.929411764705882 1" />
            </material>
        </visual>
        <collision>
            <origin rpy="0 0 0" xyz="0 0 0" />
            <geometry>
                <mesh filename="package://rm_65_description/meshes/gripper_meshes/gripper_base_link.STL" />
            </geometry>
        </collision>
    </link>
    <link name="gripper_Link1">
        
<inertial>
            <origin rpy="0 0 0" xyz="0.0164149658242926 9.75754915755189E-09 0.00898193900447147" />
            <mass value="0.00647716099397792" />
            <inertia ixx="2.95068972140683E-07" ixy="8.63208170411155E-13" ixz="-1.92008628754607E-09" iyy="1.69979619476872E-06" iyz="-1.99232397395103E-13" izz="1.45016449434989E-06" />
        </inertial>

        <visual>
            <origin rpy="0 0 0" xyz="0 0 0" />
            <geometry>
                <mesh filename="package://rm_65_description/meshes/gripper_meshes/gripper_Link1.STL" />
            </geometry>
            <material name="">
                <color rgba="0.894117647058823 0.913725490196078 0.929411764705882 1" />
            </material>
        </visual>
        <collision>
            <origin rpy="0 0 0" xyz="0 0 0" />
            <geometry>
                <mesh filename="package://rm_65_description/meshes/gripper_meshes/gripper_Link1.STL" />
            </geometry>
        </collision>
    </link>
    <joint name="gripper_Link1" type="revolute">
        <origin rpy="-3.0158E-16 -7.1586E-16 -0.30719" xyz="0.036 -0.04 -0.019" />
        <parent link="gripper_base_link" />
        <child link="gripper_Link1" />
        <axis xyz="0 0 1" />
        <limit effort="1" lower="0" upper="1" velocity="1" />
    </joint>
    <link name="gripper_Link11">
        
<inertial>
            <origin rpy="0 0 0" xyz="0.011366555972498 0.0118642725662323 0.0060000073930068" />
            <mass value="0.0127543420299361" />
            <inertia ixx="5.68538478020233E-07" ixy="-2.68012262729007E-07" ixz="9.34125984931838E-13" iyy="1.45145776457487E-06" iyz="9.34355360561326E-13" izz="1.50564598220449E-06" />
        </inertial>

        <visual>
            <origin rpy="0 0 0" xyz="0 0 0" />
            <geometry>
                <mesh filename="package://rm_65_description/meshes/gripper_meshes/gripper_Link11.STL" />
            </geometry>
            <material name="">
                <color rgba="0.894117647058823 0.913725490196078 0.929411764705882 1" />
            </material>
        </visual>
        <collision>
            <origin rpy="0 0 0" xyz="0 0 0" />
            <geometry>
                <mesh filename="package://rm_65_description/meshes/gripper_meshes/gripper_Link11.STL" />
            </geometry>
        </collision>
    </link>
    <joint name="gripper_Link11" type="revolute">
        <origin rpy="5.0393E-16 5.6225E-16 0.30719" xyz="0.042 0 0.003" />
        <parent link="gripper_Link1" />
        <child link="gripper_Link11" />
        <axis xyz="0 0 1" />
        <limit effort="1" lower="-1" upper="0" velocity="1" />
    </joint>
    <link name="gripper_Link2">
        
<inertial>
            <origin rpy="0 0 0" xyz="0.0164149658242926 9.75754915755189E-09 0.00898193900447147" />
            <mass value="0.00647716099397793" />
            <inertia ixx="2.95068972140683E-07" ixy="8.63208169650113E-13" ixz="-1.92008628755341E-09" iyy="1.69979619476872E-06" iyz="-1.99232397320157E-13" izz="1.45016449434989E-06" />
        </inertial>

        <visual>
            <origin rpy="0 0 0" xyz="0 0 0" />
            <geometry>
                <mesh filename="package://rm_65_description/meshes/gripper_meshes/gripper_Link2.STL" />
            </geometry>
            <material name="">
                <color rgba="0.894117647058823 0.913725490196078 0.929411764705882 1" />
            </material>
        </visual>
        <collision>
            <origin rpy="0 0 0" xyz="0 0 0" />
            <geometry>
                <mesh filename="package://rm_65_description/meshes/gripper_meshes/gripper_Link2.STL" />
            </geometry>
        </collision>
    </link>
    <joint name="gripper_Link2" type="revolute">
        <origin rpy="-2.6397E-16 3.7199E-16 0.30719" xyz="0.036 0.04 -0.019" />
        <parent link="gripper_base_link" />
        <child link="gripper_Link2" />
        <axis xyz="0 0 1" />
        <limit effort="1" lower="-1" upper="0" velocity="1" />
    </joint>
    <link name="gripper_Link22">
        
<inertial>
            <origin rpy="0 0 0" xyz="-0.011366555972498 0.0118642725662323 -0.0060000073930068" />
            <mass value="0.0127543420299362" />
            <inertia ixx="5.68538478020238E-07" ixy="2.6801226272901E-07" ixz="9.34125986250171E-13" iyy="1.45145776457489E-06" iyz="-9.34355361631596E-13" izz="1.5056459822045E-06" />
        </inertial>

        <visual>
            <origin rpy="0 0 0" xyz="0 0 0" />
            <geometry>
                <mesh filename="package://rm_65_description/meshes/gripper_meshes/gripper_Link22.STL" />
            </geometry>
            <material name="">
                <color rgba="0.894117647058823 0.913725490196078 0.929411764705882 1" />
            </material>
        </visual>
        <collision>
            <origin rpy="0 0 0" xyz="0 0 0" />
            <geometry>
                <mesh filename="package://rm_65_description/meshes/gripper_meshes/gripper_Link22.STL" />
            </geometry>
        </collision>
    </link>
    <joint name="gripper_Link22" type="revolute">
        <origin rpy="-3.641E-16 2.4584E-16 2.8344" xyz="0.042 0 0.015" />
        <parent link="gripper_Link2" />
        <child link="gripper_Link22" />
        <axis xyz="0 0 1" />
        <limit effort="1" lower="0" upper="1" velocity="1" />
    </joint>
    <joint name="joint9" type="fixed">
        <origin rpy="0 -1.5708 0" xyz="-0.0125 0 0.0516" />
        <parent link="plate" />
        <child link="gripper_base_link" />
        <dynamics damping="50" friction="1" />
    </joint>
    
<transmission name="tran1">
        <type>transmission_interface/SimpleTransmission</type>
        <joint name="joint1">
            <hardwareInterface>hardware_interface/PositionJointInterface</hardwareInterface>
        </joint>
        <actuator name="motor1">
            <hardwareInterface>hardware_interface/PositionJointInterface</hardwareInterface>
            <mechanicalReduction>1</mechanicalReduction>
        </actuator>
    </transmission>
    <transmission name="tran1">
        <type>transmission_interface/SimpleTransmission</type>
        <joint name="joint2">
            <hardwareInterface>hardware_interface/PositionJointInterface</hardwareInterface>
        </joint>
        <actuator name="motor1">
            <hardwareInterface>hardware_interface/PositionJointInterface</hardwareInterface>
            <mechanicalReduction>1</mechanicalReduction>
        </actuator>
    </transmission>
    <transmission name="tran1">
        <type>transmission_interface/SimpleTransmission</type>
        <joint name="joint3">
            <hardwareInterface>hardware_interface/PositionJointInterface</hardwareInterface>
        </joint>
        <actuator name="motor1">
            <hardwareInterface>hardware_interface/PositionJointInterface</hardwareInterface>
            <mechanicalReduction>1</mechanicalReduction>
        </actuator>
    </transmission>
    <transmission name="tran1">
        <type>transmission_interface/SimpleTransmission</type>
        <joint name="joint4">
            <hardwareInterface>hardware_interface/PositionJointInterface</hardwareInterface>
        </joint>
        <actuator name="motor1">
            <hardwareInterface>hardware_interface/PositionJointInterface</hardwareInterface>
            <mechanicalReduction>1</mechanicalReduction>
        </actuator>
    </transmission>
    <transmission name="tran1">
        <type>transmission_interface/SimpleTransmission</type>
        <joint name="joint5">
            <hardwareInterface>hardware_interface/PositionJointInterface</hardwareInterface>
        </joint>
        <actuator name="motor1">
            <hardwareInterface>hardware_interface/PositionJointInterface</hardwareInterface>
            <mechanicalReduction>1</mechanicalReduction>
        </actuator>
    </transmission>
    <transmission name="tran1">
        <type>transmission_interface/SimpleTransmission</type>
        <joint name="joint6">
            <hardwareInterface>hardware_interface/PositionJointInterface</hardwareInterface>
        </joint>
        <actuator name="motor1">
            <hardwareInterface>hardware_interface/PositionJointInterface</hardwareInterface>
            <mechanicalReduction>1</mechanicalReduction>
        </actuator>
    </transmission>
    <transmission name="tran1">
        <type>transmission_interface/SimpleTransmission</type>
        <joint name="gripper_Link1">
            <hardwareInterface>hardware_interface/PositionJointInterface</hardwareInterface>
        </joint>
        <actuator name="motor1">
            <hardwareInterface>hardware_interface/PositionJointInterface</hardwareInterface>
            <mechanicalReduction>1</mechanicalReduction>
        </actuator>
    </transmission>
    <transmission name="tran1">
        <type>transmission_interface/SimpleTransmission</type>
        <joint name="gripper_Link2">
            <hardwareInterface>hardware_interface/PositionJointInterface</hardwareInterface>
        </joint>
        <actuator name="motor1">
            <hardwareInterface>hardware_interface/PositionJointInterface</hardwareInterface>
            <mechanicalReduction>1</mechanicalReduction>
        </actuator>
    </transmission>
    <transmission name="tran1">
        <type>transmission_interface/SimpleTransmission</type>
        <joint name="gripper_Link11">
            <hardwareInterface>hardware_interface/PositionJointInterface</hardwareInterface>
        </joint>
        <actuator name="motor1">
            <hardwareInterface>hardware_interface/PositionJointInterface</hardwareInterface>
            <mechanicalReduction>1</mechanicalReduction>
        </actuator>
    </transmission>
    <transmission name="tran1">
        <type>transmission_interface/SimpleTransmission</type>
        <joint name="gripper_Link22">
            <hardwareInterface>hardware_interface/PositionJointInterface</hardwareInterface>
        </joint>
        <actuator name="motor1">
            <hardwareInterface>hardware_interface/PositionJointInterface</hardwareInterface>
            <mechanicalReduction>1</mechanicalReduction>
        </actuator>
    </transmission>
    <!-- gazebo controller plugin for arm -->
    <gazebo>
        <plugin filename="libgazebo_ros_control.so" name="gazebo_ros_control">
            <robotNamespace>/</robotNamespace>
            <robotSimType>gazebo_ros_control/DefaultRobotHWSim</robotSimType>
            <legacyModeNS>true</legacyModeNS>
        </plugin>
    </gazebo>
    <!-- gazebo controller plugin for gripper -->
    <transmission name="trans_joint1">
        <type>transmission_interface/SimpleTransmission</type>
        <joint name="joint1">
            <hardwareInterface>hardware_interface/EffortJointInterface</hardwareInterface>
        </joint>
        <actuator name="joint1_motor">
            <hardwareInterface>hardware_interface/EffortJointInterface</hardwareInterface>
            <mechanicalReduction>1</mechanicalReduction>
        </actuator>
    </transmission>
    <transmission name="trans_joint2">
        <type>transmission_interface/SimpleTransmission</type>
        <joint name="joint2">
            <hardwareInterface>hardware_interface/EffortJointInterface</hardwareInterface>
        </joint>
        <actuator name="joint2_motor">
            <hardwareInterface>hardware_interface/EffortJointInterface</hardwareInterface>
            <mechanicalReduction>1</mechanicalReduction>
        </actuator>
    </transmission>
    <transmission name="trans_joint3">
        <type>transmission_interface/SimpleTransmission</type>
        <joint name="joint3">
            <hardwareInterface>hardware_interface/EffortJointInterface</hardwareInterface>
        </joint>
        <actuator name="joint3_motor">
            <hardwareInterface>hardware_interface/EffortJointInterface</hardwareInterface>
            <mechanicalReduction>1</mechanicalReduction>
        </actuator>
    </transmission>
    <transmission name="trans_joint4">
        <type>transmission_interface/SimpleTransmission</type>
        <joint name="joint4">
            <hardwareInterface>hardware_interface/EffortJointInterface</hardwareInterface>
        </joint>
        <actuator name="joint4_motor">
            <hardwareInterface>hardware_interface/EffortJointInterface</hardwareInterface>
            <mechanicalReduction>1</mechanicalReduction>
        </actuator>
    </transmission>
    <transmission name="trans_joint5">
        <type>transmission_interface/SimpleTransmission</type>
        <joint name="joint5">
            <hardwareInterface>hardware_interface/EffortJointInterface</hardwareInterface>
        </joint>
        <actuator name="joint5_motor">
            <hardwareInterface>hardware_interface/EffortJointInterface</hardwareInterface>
            <mechanicalReduction>1</mechanicalReduction>
        </actuator>
    </transmission>
    <transmission name="trans_joint6">
        <type>transmission_interface/SimpleTransmission</type>
        <joint name="joint6">
            <hardwareInterface>hardware_interface/EffortJointInterface</hardwareInterface>
        </joint>
        <actuator name="joint6_motor">
            <hardwareInterface>hardware_interface/EffortJointInterface</hardwareInterface>
            <mechanicalReduction>1</mechanicalReduction>
        </actuator>
    </transmission>
    <transmission name="trans_gripper_Link1">
        <type>transmission_interface/SimpleTransmission</type>
        <joint name="gripper_Link1">
            <hardwareInterface>hardware_interface/EffortJointInterface</hardwareInterface>
        </joint>
        <actuator name="gripper_Link1_motor">
            <hardwareInterface>hardware_interface/EffortJointInterface</hardwareInterface>
            <mechanicalReduction>1</mechanicalReduction>
        </actuator>
    </transmission>
    <transmission name="trans_gripper_Link11">
        <type>transmission_interface/SimpleTransmission</type>
        <joint name="gripper_Link11">
            <hardwareInterface>hardware_interface/EffortJointInterface</hardwareInterface>
        </joint>
        <actuator name="gripper_Link11_motor">
            <hardwareInterface>hardware_interface/EffortJointInterface</hardwareInterface>
            <mechanicalReduction>1</mechanicalReduction>
        </actuator>
    </transmission>
    <transmission name="trans_gripper_Link2">
        <type>transmission_interface/SimpleTransmission</type>
        <joint name="gripper_Link2">
            <hardwareInterface>hardware_interface/EffortJointInterface</hardwareInterface>
        </joint>
        <actuator name="gripper_Link2_motor">
            <hardwareInterface>hardware_interface/EffortJointInterface</hardwareInterface>
            <mechanicalReduction>1</mechanicalReduction>
        </actuator>
    </transmission>
    <transmission name="trans_gripper_Link22">
        <type>transmission_interface/SimpleTransmission</type>
        <joint name="gripper_Link22">
            <hardwareInterface>hardware_interface/EffortJointInterface</hardwareInterface>
        </joint>
        <actuator name="gripper_Link22_motor">
            <hardwareInterface>hardware_interface/EffortJointInterface</hardwareInterface>
            <mechanicalReduction>1</mechanicalReduction>
        </actuator>
    </transmission>
    <gazebo>
        <plugin name="gazebo_ros_control" filename="libgazebo_ros_control.so">
            <robotNamespace>/</robotNamespace>
        </plugin>
    </gazebo>
</robot>
