<?xml version="1.0" encoding="utf-8"?>
<robot  name="rm_65" xmlns:xacro="http://www.ros.org/wiki/xacro">
<xacro:include filename="$(find rm_65_description)/urdf/rm_65.transmission.xacro"/>
<xacro:include filename="$(find rm_65_description)/urdf/rm_65.gazebo.xacro"/>

  

  <link name="dummy">
  </link>
  

  <!-- base_link -->
  <link
    name="base_link">
    <inertial>
      <origin
        xyz="0 0 0"
        rpy="0 0 0" />
      <mass
        value="140" />
      <inertia
        ixx="0.01"
        ixy="0"
        ixz="0"
        iyy="0.01"
        iyz="0"
        izz="0.01" />
    </inertial>
    <visual>
      <origin
        xyz="0 0 0"
        rpy="0 0 0" />
      <geometry>
        <mesh
          filename="package://rm_65_description/meshes/base_link.STL" />
      </geometry>
      <material
        name="">
        <color
          rgba="1 1 1 1" />
      </material>
    </visual>
    <collision>
      <origin
        xyz="0 0 0"
        rpy="0 0 0" />
      <geometry>
        <mesh
          filename="package://rm_65_description/meshes/base_link.STL" />
      </geometry>
    </collision>
  </link>
  
  
  <gazebo reference="base_link">
    <mu1 value="200000.0"/>
    <mu2 value="200000.0"/>
    <kp value="100000000.0"/>
    <kd value="1.0"/>
    <kinematic>1</kinematic>
  </gazebo>
  

  <joint name="dummy_joint" type="fixed">
    <parent link="dummy" />
    <child link="base_link" />
  </joint>

  
  <!-- Link1 -->
  <link
    name="Link1">
    <inertial>
      <origin
        xyz="1.2226305431569E-08 0.0211079974844683 -0.0251854220842269"
        rpy="0 0 0" />
      <mass
        value="0.593563443690403" />
      <inertia
        ixx="0.00126614120341847"
        ixy="-1.294980943835E-08"
        ixz="-9.80120923066996E-09"
        iyy="0.00118168178300364"
        iyz="-0.00021121727444415"
        izz="0.00056135241627747" />
    </inertial>
    <visual>
      <origin
        xyz="0 0 0"
        rpy="0 0 0" />
      <geometry>
        <mesh
          filename="package://rm_65_description/meshes/link1.STL" />
      </geometry>
      <material
        name="">
        <color
          rgba="1 1 1 1" />
      </material>
    </visual>
    <collision>
      <origin
        xyz="0 0 0"
        rpy="0 0 0" />
      <geometry>
        <mesh
          filename="package://rm_65_description/meshes/link1.STL" />
      </geometry>
    </collision>
  </link>
  <joint
    name="joint1"
    type="revolute">
    <origin
      xyz="0 0 0.2405"
      rpy="0 0 0" />
    <parent
      link="base_link" />
    <child
      link="Link1" />
    <axis
      xyz="0 0 1" />

    <limit
      lower="-3.14"
      upper="3.14"
      effort="60"
      velocity="3.14" />

  </joint>

  <gazebo reference="link1">
    <mu1 value="200000.0"/>
    <mu2 value="200000.0"/>
    <kp value="100000000.0"/>
    <kd value="1.0"/>
    <kinematic>1</kinematic>
  </gazebo>

  <!-- Link2 -->
  <link
    name="Link2">
    <inertial>
      <origin
        xyz="0.152256463426163 4.75383656106654E-07 -0.00620260383607792"
        rpy="0 0 0" />
      <mass
        value="0.13" />
      <inertia
        ixx="0.00089150298478414"
        ixy="-2.23268489334765E-08"
        ixz="0.00156246461035015"
        iyy="0.00733754343083901"
        iyz="6.28110889329165E-09"
        izz="0.00697869103915473" />
    </inertial>
    <visual>
      <origin
        xyz="0 0 0"
        rpy="0 0 0" />
      <geometry>
        <mesh
          filename="package://rm_65_description/meshes/link2.STL" />
      </geometry>
      <material
        name="">
        <color
          rgba="1 1 1 1" />
      </material>
    </visual>
    <collision>
      <origin
        xyz="0 0 0"
        rpy="0 0 0" />
      <geometry>
        <mesh
          filename="package://rm_65_description/meshes/link2.STL" />
      </geometry>
    </collision>
  </link>
  <joint
    name="joint2"
    type="revolute">
    <origin
      xyz="0 0 0"
      rpy="1.5708 -1.5708 0" />
    <parent
      link="Link1" />
    <child
      link="Link2" />
    <axis
      xyz="0 0 1" />

    <limit
      lower="-2.268"
      upper="2.268"
      effort="60"
      velocity="3.14" />

	<dynamics damping="50" friction="1"/>
  </joint>

  <!-- Link3 -->
  <link
    name="Link3">
    <inertial>
      <origin
        xyz="5.05312670989961E-06 -0.0595925663694732 0.010569069212336"
        rpy="0 0 0" />
      <mass
        value="0.13" />
      <inertia
        ixx="0.00063737100450158"
        ixy="-7.05261293649751E-08"
        ixz="-3.86643272239426E-08"
        iyy="0.00015648388095025"
        iyz="-0.00014461035994916"
        izz="0.000614178164773085" />
    </inertial>
    <visual>
      <origin
        xyz="0 0 0"
        rpy="0 0 0" />
      <geometry>
        <mesh
          filename="package://rm_65_description/meshes/link3.STL" />
      </geometry>
      <material
        name="">
        <color
          rgba="1 1 1 1" />
      </material>
    </visual>
    <collision>
      <origin
        xyz="0 0 0"
        rpy="0 0 0" />
      <geometry>
        <mesh
          filename="package://rm_65_description/meshes/link3.STL" />
      </geometry>
    </collision>
  </link>
  <joint
    name="joint3"
    type="revolute">
    <origin
      xyz="0.256 0 0"
      rpy="0 0 1.5708" />
    <parent
      link="Link2" />
    <child
      link="Link3" />
    <axis
      xyz="0 0 1" />

    <limit
      lower="-2.355"
      upper="2.355"
      effort="30"
      velocity="3.92" />

	<dynamics damping="50" friction="1"/>
  </joint>


  <!-- Link4 -->
  <link
    name="Link4">
    <inertial>
      <origin
        xyz="1.15516617405898E-06 -0.0180424468598241 -0.0215394748352687"
        rpy="0 0 0" />
      <mass
        value="0.13" />
      <inertia
        ixx="0.000285938919722783"
        ixy="3.07101359163101E-09"
        ixz="-2.21994118981953E-09"
        iyy="0.000262727540304212"
        iyz="4.4236583260078E-05"
        izz="0.000119888082791859" />
    </inertial>
    <visual>
      <origin
        xyz="0 0 0"
        rpy="0 0 0" />
      <geometry>
        <mesh
          filename="package://rm_65_description/meshes/link4.STL" />
      </geometry>
      <material
        name="">
        <color
          rgba="1 1 1 1" />
      </material>
    </visual>
    <collision>
      <origin
        xyz="0 0 0"
        rpy="0 0 0" />
      <geometry>
        <mesh
          filename="package://rm_65_description/meshes/link4.STL" />
      </geometry>
    </collision>
  </link>
  <joint
    name="joint4"
    type="revolute">
    <origin
      xyz="0 -0.21 0"
      rpy="1.5708 0 0" />
    <parent
      link="Link3" />
    <child
      link="Link4" />
    <axis
      xyz="0 0 1" />

    <limit
      lower="-3.14"
      upper="3.14"
      effort="10"
      velocity="3.92" />

	<dynamics damping="50" friction="1"/>
  </joint>

  <!-- Link5 -->
  <link
    name="Link5">
    <inertial>
      <origin
        xyz="3.19794786262152E-06 -0.0593808368101458 0.00736804250989326"
        rpy="0 0 0" />
      <mass
        value="0.13" />
      <inertia
        ixx="0.000350540363914072"
        ixy="-3.41781619975602E-08"
        ixz="-1.77056457224373E-08"
        iyy="0.000104927867487581"
        iyz="-7.82431228461971E-05"
        izz="0.000334482418423629" />
    </inertial>
    <visual>
      <origin
        xyz="0 0 0"
        rpy="0 0 0" />
      <geometry>
        <mesh
          filename="package://rm_65_description/meshes/link5.STL" />
      </geometry>
      <material
        name="">
        <color
          rgba="1 1 1 1" />
      </material>
    </visual>
    <collision>
      <origin
        xyz="0 0 0"
        rpy="0 0 0" />
      <geometry>
        <mesh
          filename="package://rm_65_description/meshes/link5.STL" />
      </geometry>
    </collision>
  </link>
  <joint
    name="joint5"
    type="revolute">
    <origin
      xyz="0 0 0"
      rpy="-1.5708 0 0" />
    <parent
      link="Link4" />
    <child
      link="Link5" />
    <axis
      xyz="0 0 1" />

    <limit
      lower="-2.233"
      upper="2.233"
      effort="10"
      velocity="3.92" />

	<dynamics damping="50" friction="1"/>
  </joint>

  <!-- Link6 -->
  <link
    name="Link6">
    <inertial>
      <origin
        xyz="0.000714234511756999 -0.000396718732824521 -0.0126723660946126"
        rpy="0 0 0" />
      <mass
        value="0.13" />
      <inertia
        ixx="0.01"
        ixy="0.01"
        ixz="0.01"
        iyy="0.01"
        iyz="0.01"
        izz="0.01" />
    </inertial>
    <visual>
      <origin
        xyz="0 0 0"
        rpy="0 0 0" />
      <geometry>
        <mesh
          filename="package://rm_65_description/meshes/link6.STL" />
      </geometry>
      <material
        name="">
        <color
          rgba="1 1 1 1" />
      </material>
    </visual>
    <collision>
      <origin
        xyz="0 0 0"
        rpy="0 0 0" />
      <geometry>
        <mesh
          filename="package://rm_65_description/meshes/link6.STL" />
      </geometry>
    </collision>
  </link>

  <joint
    name="joint6"
    type="continuous">
    <origin
      xyz="0 -0.144 0"
      rpy="1.5708 0 0" />
    <parent
      link="Link5" />
    <child
      link="Link6" />
    <axis
      xyz="0 0 1" />

    <limit
      lower="-6.28"
      upper="6.28"
      effort="10"
      velocity="3.92" />

    <dynamics damping="50" friction="1"/>
  </joint>

  <!-- plate   -2.25539999752262E-10   -->
  <link
    name="plate">
    <inertial>
      <origin
        xyz="0.04582 -2.25539999752262E-10 0.004046"
        rpy="1.5708 0 0" />
      <mass
        value="0.01" />
      <inertia
        ixx="0.01"
        ixy="0"
        ixz="0"
        iyy="0.01"
        iyz="0"
        izz="0.01" />
    </inertial>
    <visual>
      <origin
        xyz="0 0 0"
        rpy="1.5708 0 0" />
      <geometry>
        <mesh
          filename="package://rm_65_description/meshes/plate.STL" />
      </geometry>
      <material
        name="">
        <color
          rgba="1 1 1 1" />
      </material>
    </visual>
    <collision>
      <origin
        xyz="0 0 0"
        rpy="1.5708 0 0" />
      <geometry>
        <mesh
          filename="package://rm_65_description/meshes/plate.STL" />
      </geometry>
    </collision>
  </link>

  <joint
    name="joint_plate"
    type="fixed">
    <origin
      xyz="0 0 0"
      rpy="0 0 3.1415" />
    <parent
      link="Link6" />
    <child
      link="plate" />
  </joint>

  <gazebo reference="plate">
    <kinematic>1</kinematic>
  </gazebo>
  
  <!-- realsense d435 with gazebo simulation    joint8  -->
  <xacro:include filename="$(find realsense_ros_gazebo)/xacro/depthcam.xacro"/>

  <xacro:realsense_d435 sensor_name="d435" parent_link="plate" rate="10">
    <origin rpy="0 -1.5708 3.1415" xyz="0.08 0 0.0185"/>
  </xacro:realsense_d435>
  
  
  <!--
  <xacro:arg name="use_nominal_extrinsics" default="false"/>
  <xacro:arg name="add_plug" default="false" />
  <xacro:arg name="use_mesh" default="true" />
  <xacro:include filename="$(find realsense2_description)/urdf/_d435.urdf.xacro" />

  <xacro:sensor_d435 parent="plate" use_nominal_extrinsics="$(arg use_nominal_extrinsics)" add_plug="$(arg add_plug)" use_mesh="$(arg use_mesh)">
    <origin xyz="0.08 0 0.0185" rpy="0 -1.5708 3.1416"/>
    <origin xyz="0.0925 0 0.008" rpy="0 -1.5708 0"/>
  </xacro:sensor_d435>
  -->
  
  <!-- gripper -->
  <xacro:include filename="$(find rm_65_description)/urdf/jawasm1.urdf.xacro" />

  <joint
    name="joint9"
    type="fixed">
    <origin
      xyz="-0.0125 0 0.0516"
      rpy="0 -1.5708 0" />
    <parent
      link="plate" />
    <child
      link="gripper_base_link" />
    <dynamics damping="50" friction="1" />
  </joint>

  <gazebo reference="gripper_base_link">
    <mu1 value="200000.0"/>
    <mu2 value="200000.0"/>
    <kp value="100000000.0"/>
    <kd value="1.0"/>
    <kinematic>1</kinematic>
  </gazebo>

  <!--           Transmissions for ROS Control            -->
  <xacro:macro name="transmission_block" params="joint_name" >
    <transmission name="tran1">
      <type>transmission_interface/SimpleTransmission</type>
      <joint name="${joint_name}">
        <hardwareInterface>hardware_interface/PositionJointInterface</hardwareInterface>
      </joint>
      <actuator name="motor1">
        <hardwareInterface>hardware_interface/PositionJointInterface</hardwareInterface>
        <mechanicalReduction>1</mechanicalReduction>
      </actuator>
    </transmission>
  </xacro:macro>
    
  <xacro:transmission_block joint_name="joint1"/>
  <xacro:transmission_block joint_name="joint2"/>
  <xacro:transmission_block joint_name="joint3"/>
  <xacro:transmission_block joint_name="joint4"/>
  <xacro:transmission_block joint_name="joint5"/>
  <xacro:transmission_block joint_name="joint6"/>

  <xacro:transmission_block joint_name="gripper_Link1"/>
  <xacro:transmission_block joint_name="gripper_Link2"/>
  <xacro:transmission_block joint_name="gripper_Link11"/>
  <xacro:transmission_block joint_name="gripper_Link22"/>

  <!-- gazebo controller plugin for arm -->
  <gazebo>
    <plugin name="gazebo_ros_control" filename="libgazebo_ros_control.so">
      <robotNamespace>/arm</robotNamespace>
      <robotSimType>gazebo_ros_control/DefaultRobotHWSim</robotSimType>
      <legacyModeNS>true</legacyModeNS>
    </plugin>
  </gazebo>

  <!-- gazebo controller plugin for gripper -->
  <gazebo>
      <!-- loading plugin: mimic joints works in gazebo now -->
      <plugin filename="libroboticsgroup_upatras_gazebo_mimic_joint_plugin.so" name="gripper_joint11_plugin">
          <joint>gripper_Link1</joint>
          <mimicJoint>gripper_Link11</mimicJoint>
          <multiplier>1.0</multiplier>
          <offset>0.0</offset>
      </plugin>
      <plugin filename="libroboticsgroup_upatras_gazebo_mimic_joint_plugin.so" name="gripper_joint2_plugin">
          <joint>gripper_Link1</joint>
          <mimicJoint>gripper_Link2</mimicJoint>
          <multiplier>1.0</multiplier>
          <offset>0.0</offset>
      </plugin>
      <plugin filename="libroboticsgroup_upatras_gazebo_mimic_joint_plugin.so" name="gripper_joint22_plugin">
          <joint>gripper_Link1</joint>
          <mimicJoint>gripper_Link22</mimicJoint>
          <multiplier>1.0</multiplier>
          <offset>0.0</offset>
      </plugin>
  </gazebo>
</robot>
